Workbook

Sheet 01_신청서
A1: M211 렌더팜 사용 신청서
A2: 팀별로 한 줄씩 작성해주세요. 분량은 최종 상영 길이(분) 기준입니다. 회색 칸은 자동 계산되니 건드리지 마세요.
A4: No. | B4: 팀 프로젝트명 | C4: 팀장 학번 | D4: 팀장 이메일 | E4: 프로젝트 분량(분) | F4: 라이선스 | G4: 주 타임블럭 | H4: 주 사용시간 | I4: 신청일 | J4: 비고
A5: 1 | F5: =IF(E5="","",IF(E5<=3,1,IF(E5<=6,2,3))) | G5: =IF(F5="","",F5*8) | H5: =IF(G5="","",G5*4)
A6: 2 | F6: =IF(E6="","",IF(E6<=3,1,IF(E6<=6,2,3))) | G6: =IF(F6="","",F6*8) | H6: =IF(G6="","",G6*4)
A7: 3 | F7: =IF(E7="","",IF(E7<=3,1,IF(E7<=6,2,3))) | G7: =IF(F7="","",F7*8) | H7: =IF(G7="","",G7*4)
A8: 4 | F8: =IF(E8="","",IF(E8<=3,1,IF(E8<=6,2,3))) | G8: =IF(F8="","",F8*8) | H8: =IF(G8="","",G8*4)
A9: 5 | F9: =IF(E9="","",IF(E9<=3,1,IF(E9<=6,2,3))) | G9: =IF(F9="","",F9*8) | H9: =IF(G9="","",G9*4)
A10: 6 | F10: =IF(E10="","",IF(E10<=3,1,IF(E10<=6,2,3))) | G10: =IF(F10="","",F10*8) | H10: =IF(G10="","",G10*4)
A11: 7 | F11: =IF(E11="","",IF(E11<=3,1,IF(E11<=6,2,3))) | G11: =IF(F11="","",F11*8) | H11: =IF(G11="","",G11*4)
A12: 8 | F12: =IF(E12="","",IF(E12<=3,1,IF(E12<=6,2,3))) | G12: =IF(F12="","",F12*8) | H12: =IF(G12="","",G12*4)
A13: 9 | F13: =IF(E13="","",IF(E13<=3,1,IF(E13<=6,2,3))) | G13: =IF(F13="","",F13*8) | H13: =IF(G13="","",G13*4)
A14: 10 | F14: =IF(E14="","",IF(E14<=3,1,IF(E14<=6,2,3))) | G14: =IF(F14="","",F14*8) | H14: =IF(G14="","",G14*4)
A15: 11 | F15: =IF(E15="","",IF(E15<=3,1,IF(E15<=6,2,3))) | G15: =IF(F15="","",F15*8) | H15: =IF(G15="","",G15*4)
A16: 12 | F16: =IF(E16="","",IF(E16<=3,1,IF(E16<=6,2,3))) | G16: =IF(F16="","",F16*8) | H16: =IF(G16="","",G16*4)
... A34: 30 | F34: =IF(E34="","",IF(E34<=3,1,IF(E34<=6,2,3))) | G34: =IF(F34="","",F34*8) | H34: =IF(G34="","",G34*4)
B36: 합계 | F36: =SUM(F5:F34) | G36: =SUM(G5:G34) | H36: =SUM(H5:H34)
B37: =IF(G36="","",IF(G36<=128,"수용 가능 — 주간 공급 128블럭 중 "&G36&"블럭 신청","초과 — 주간 공급 128블럭보다 "&(G36-128)&"블럭 많습니다. 산정 기준 조정 필요"))
B40: 분량 → 라이선스 산정 기준
B41: 3분 이하 | C41: 라이선스 1 · 주 8블럭 · 32시간
B42: 3분 초과 ~ 6분 이하 | C42: 라이선스 2 · 주 16블럭 · 64시간
B43: 6분 초과 | C43: 라이선스 3 · 주 24블럭 · 96시간
B45: 주간 공급량 | C45: 평일 5일×4블럭×4그룹 = 80 + 주말 2일×6블럭×4그룹 = 48 → 총 128블럭

Sheet 02_예약표
A1: 예약표
A2: 빈 칸에 본인 학번을 입력하세요. 회색 칸은 수업 시간이라 사용할 수 없습니다. 제출할 때 반드시 예약한 그룹을 지정하세요.
A4: 1주차 10/19 ~ 10/25
A5: 주차 | B5: 타임블럭 | C5: 그룹 | D5: 월 10/19 | E5: 화 10/20 | F5: 수 10/21 | G5: 목 10/22 | H5: 금 10/23 | I5: 토 10/24 | J5: 일 10/25
A6: 1주 | B6: 19:00-23:00 | C6: A
A7: 1주 | C7: B
A8: 1주 | C8: C
A9: 1주 | C9: D
A10: 1주 | B10: 23:00-03:00 | C10: A
A11: 1주 | C11: B
A12: 1주 | C12: C
A13: 1주 | C13: D
A14: 1주 | B14: 03:00-07:00 | C14: A
A15: 1주 | C15: B
A16: 1주 | C16: C
A17: 1주 | C17: D
A18: 1주 | B18: 07:00-11:00 | C18: A
A19: 1주 | C19: B
A20: 1주 | C20: C
A21: 1주 | C21: D
A22: 1주 | B22: 11:00-15:00 | C22: A | D22: 수업 시간
A23: 1주 | C23: B
A24: 1주 | C24: C
A25: 1주 | C25: D
A26: 1주 | B26: 15:00-19:00 | C26: A | D26: 수업 시간
A27: 1주 | C27: B
A28: 1주 | C28: C
A29: 1주 | C29: D
A31: 2주차 10/26 ~ 11/01
A32: 주차 | B32: 타임블럭 | C32: 그룹 | D32: 월 10/26 | E32: 화 10/27 | F32: 수 10/28 | G32: 목 10/29 | H32: 금 10/30 | I32: 토 10/31 | J32: 일 11/01
A33: 2주 | B33: 19:00-23:00 | C33: A
A34: 2주 | C34: B
A35: 2주 | C35: C
A36: 2주 | C36: D
A37: 2주 | B37: 23:00-03:00 | C37: A
A38: 2주 | C38: B
A39: 2주 | C39: C
A40: 2주 | C40: D
A41: 2주 | B41: 03:00-07:00 | C41: A
A42: 2주 | C42: B
...

Sheet 03_사용현황
A1: 사용 현황
A2: 신청서와 예약표에서 자동으로 계산됩니다. 남은 블럭이 빨간색이면 상한을 초과한 것입니다.
A4: 팀 프로젝트명 | B4: 학번 | C4: 주 최대 | D4: 1주차 사용 | E4: 2주차 사용 | F4: 3주차 사용 | G4: 4주차 사용 | H4: 1주차 남음 | I4: 2주차 남음 | J4: 3주차 남음 | K4: 4주차 남음
A5: =IF('01_신청서'!B5="","",'01_신청서'!B5) | B5: =IF('01_신청서'!C5="","",'01_신청서'!C5) | C5: =IF('01_신청서'!G5="","",'01_신청서'!G5) | D5: =IF($B5="","",COUNTIF('02_예약표'!$D$6:$J$29,$B5)) | E5: =IF($B5="","",COUNTIF('02_예약표'!$D$33:$J$56,$B5)) | F5: =IF($B5="","",COUNTIF('02_예약표'!$D$60:$J$83,$B5)) | G5: =IF($B5="","",COUNTIF('02_예약표'!$D$87:$J$110,$B5)) | H5: =IF($B5="","",$C5-D5) | I5: =IF($B5="","",$C5-E5) | J5: =IF($B5="","",$C5-F5) | K5: =IF($B5="","",$C5-G5)
A6: =IF('01_신청서'!B6="","",'01_신청서'!B6) | B6: =IF('01_신청서'!C6="","",'01_신청서'!C6) | C6: =IF('01_신청서'!G6="","",'01_신청서'!G6) | D6: =IF($B6="","",COUNTIF('02_예약표'!$D$6:$J$29,$B6)) | E6: =IF($B6="","",COUNTIF('02_예약표'!$D$33:$J$56,$B6)) | F6: =IF($B6="","",COUNTIF('02_예약표'!$D$60:$J$83,$B6)) | G6: =IF($B6="","",COUNTIF('02_예약표'!$D$87:$J$110,$B6)) | H6: =IF($B6="","",$C6-D6) | I6: =IF($B6="","",$C6-E6) | J6: =IF($B6="","",$C6-F6) | K6: =IF($B6="","",$C6-G6)
A7: =IF('01_신청서'!B7="","",'01_신청서'!B7) | B7: =IF('01_신청서'!C7="","",'01_신청서'!C7) | C7: =IF('01_신청서'!G7="","",'01_신청서'!G7) | D7: =IF($B7="","",COUNTIF('02_예약표'!$D$6:$J$29,$B7)) | E7: =IF($B7="","",COUNTIF('02_예약표'!$D$33:$J$56,$B7)) | F7: =IF($B7="","",COUNTIF('02_예약표'!$D$60:$J$83,$B7)) | G7: =IF($B7="","",COUNTIF('02_예약표'!$D$87:$J$110,$B7)) | H7: =IF($B7="","",$C7-D7) | I7: =IF($B7="","",$C7-E7) | J7: =IF($B7="","",$C7-F7) | K7: =IF($B7="","",$C7-G7)
A8: =IF('01_신청서'!B8="","",'01_신청서'!B8) | B8: =IF('01_신청서'!C8="","",'01_신청서'!C8) | C8: =IF('01_신청서'!G8="","",'01_신청서'!G8) | D8: =IF($B8="","",COUNTIF('02_예약표'!$D$6:$J$29,$B8)) | E8: =IF($B8="","",COUNTIF('02_예약표'!$D$33:$J$56,$B8)) | F8: =IF($B8="","",COUNTIF('02_예약표'!$D$60:$J$83,$B8)) | G8: =IF($B8="","",COUNTIF('02_예약표'!$D$87:$J$110,$B8)) | H8: =IF($B8="","",$C8-D8) | I8: =IF($B8="","",$C8-E8) | J8: =IF($B8="","",$C8-F8) | K8: =IF($B8="","",$C8-G8)
A9: =IF('01_신청서'!B9="","",'01_신청서'!B9) | B9: =IF('01_신청서'!C9="","",'01_신청서'!C9) | C9: =IF('01_신청서'!G9="","",'01_신청서'!G9) | D9: =IF($B9="","",COUNTIF('02_예약표'!$D$6:$J$29,$B9)) | E9: =IF($B9="","",COUNTIF('02_예약표'!$D$33:$J$56,$B9)) | F9: =IF($B9="","",COUNTIF('02_예약표'!$D$60:$J$83,$B9)) | G9: =IF($B9="","",COUNTIF('02_예약표'!$D$87:$J$110,$B9)) | H9: =IF($B9="","",$C9-D9) | I9: =IF($B9="","",$C9-E9) | J9: =IF($B9="","",$C9-F9) | K9: =IF($B9="","",$C9-G9)
A10: =IF('01_신청서'!B10="","",'01_신청서'!B10) | B10: =IF('01_신청서'!C10="","",'01_신청서'!C10) | C10: =IF('01_신청서'!G10="","",'01_신청서'!G10) | D10: =IF($B10="","",COUNTIF('02_예약표'!$D$6:$J$29,$B10)) | E10: =IF($B10="","",COUNTIF('02_예약표'!$D$33:$J$56,$B10)) | F10: =IF($B10="","",COUNTIF('02_예약표'!$D$60:$J$83,$B10)) | G10: =IF($B10="","",COUNTIF('02_예약표'!$D$87:$J$110,$B10)) | H10: =IF($B10="","",$C10-D10) | I10: =IF($B10="","",$C10-E10) | J10: =IF($B10="","",$C10-F10) | K10: =IF($B10="","",$C10-G10)
A11: =IF('01_신청서'!B11="","",'01_신청서'!B11) | B11: =IF('01_신청서'!C11="","",'01_신청서'!C11) | C11: =IF('01_신청서'!G11="","",'01_신청서'!G11) | D11: =IF($B11="","",COUNTIF('02_예약표'!$D$6:$J$29,$B11)) | E11: =IF($B11="","",COUNTIF('02_예약표'!$D$33:$J$56,$B11)) | F11: =IF($B11="","",COUNTIF('02_예약표'!$D$60:$J$83,$B11)) | G11: =IF($B11="","",COUNTIF('02_예약표'!$D$87:$J$110,$B11)) | H11: =IF($B11="","",$C11-D11) | I11: =IF($B11="","",$C11-E11) | J11: =IF($B11="","",$C11-F11) | K11: =IF($B11="","",$C11-G11)
A12: =IF('01_신청서'!B12="","",'01_신청서'!B12) | B12: =IF('01_신청서'!C12="","",'01_신청서'!C12) | C12: =IF('01_신청서'!G12="","",'01_신청서'!G12) | D12: =IF($B12="","",COUNTIF('02_예약표'!$D$6:$J$29,$B12)) | E12: =IF($B12="","",COUNTIF('02_예약표'!$D$33:$J$56,$B12)) | F12: =IF($B12="","",COUNTIF('02_예약표'!$D$60:$J$83,$B12)) | G12: =IF($B12="","",COUNTIF('02_예약표'!$D$87:$J$110,$B12)) | H12: =IF($B12="","",$C12-D12) | I12: =IF($B12="","",$C12-E12) | J12: =IF($B12="","",$C12-F12) | K12: =IF($B12="","",$C12-G12)
A13: =IF('01_신청서'!B13="","",'01_신청서'!B13) | B13: =IF('01_신청서'!C13="","",'01_신청서'!C13) | C13: =IF('01_신청서'!G13="","",'01_신청서'!G13) | D13: =IF($B13="","",COUNTIF('02_예약표'!$D$6:$J$29,$B13)) | E13: =IF($B13="","",COUNTIF('02_예약표'!$D$33:$J$56,$B13)) | F13: =IF($B13="","",COUNTIF('02_예약표'!$D$60:$J$83,$B13)) | G13: =IF($B13="","",COUNTIF('02_예약표'!$D$87:$J$110,$B13)) | H13: =IF($B13="","",$C13-D13) | I13: =IF($B13="","",$C13-E13) | J13: =IF($B13="","",$C13-F13) | K13: =IF($B13="","",$C13-G13)
A14: =IF('01_신청서'!B14="","",'01_신청서'!B14) | B14: =IF('01_신청서'!C14="","",'01_신청서'!C14) | C14: =IF('01_신청서'!G14="","",'01_신청서'!G14) | D14: =IF($B14="","",COUNTIF('02_예약표'!$D$6:$J$29,$B14)) | E14: =IF($B14="","",COUNTIF('02_예약표'!$D$33:$J$56,$B14)) | F14: =IF($B14="","",COUNTIF('02_예약표'!$D$60:$J$83,$B14)) | G14: =IF($B14="","",COUNTIF('02_예약표'!$D$87:$J$110,$B14)) | H14: =IF($B14="","",$C14-D14) | I14: =IF($B14="","",$C14-E14) | J14: =IF($B14="","",$C14-F14) | K14: =IF($B14="","",$C14-G14)
A15: =IF('01_신청서'!B15="","",'01_신청서'!B15) | B15: =IF('01_신청서'!C15="","",'01_신청서'!C15) | C15: =IF('01_신청서'!G15="","",'01_신청서'!G15) | D15: =IF($B15="","",COUNTIF('02_예약표'!$D$6:$J$29,$B15)) | E15: =IF($B15="","",COUNTIF('02_예약표'!$D$33:$J$56,$B15)) | F15: =IF($B15="","",COUNTIF('02_예약표'!$D$60:$J$83,$B15)) | G15: =IF($B15="","",COUNTIF('02_예약표'!$D$87:$J$110,$B15)) | H15: =IF($B15="","",$C15-D15) | I15: =IF($B15="","",$C15-E15) | J15: =IF($B15="","",$C15-F15) | K15: =IF($B15="","",$C15-G15)
A16: =IF('01_신청서'!B16="","",'01_신청서'!B16) | B16: =IF('01_신청서'!C16="","",'01_신청서'!C16) | C16: =IF('01_신청서'!G16="","",'01_신청서'!G16) | D16: =IF($B16="","",COUNTIF('02_예약표'!$D$6:$J$29,$B16)) | E16: =IF($B16="","",COUNTIF('02_예약표'!$D$33:$J$56,$B16)) | F16: =IF($B16="","",COUNTIF('02_예약표'!$D$60:$J$83,$B16)) | G16: =IF($B16="","",COUNTIF('02_예약표'!$D$87:$J$110,$B16)) | H16: =IF($B16="","",$C16-D16) | I16: =IF($B16="","",$C16-E16) | J16: =IF($B16="","",$C16-F16) | K16: =IF($B16="","",$C16-G16)
... A34: =IF('01_신청서'!B34="","",'01_신청서'!B34) | B34: =IF('01_신청서'!C34="","",'01_신청서'!C34) | C34: =IF('01_신청서'!G34="","",'01_신청서'!G34) | D34: =IF($B34="","",COUNTIF('02_예약표'!$D$6:$J$29,$B34)) | E34: =IF($B34="","",COUNTIF('02_예약표'!$D$33:$J$56,$B34)) | F34: =IF($B34="","",COUNTIF('02_예약표'!$D$60:$J$83,$B34)) | G34: =IF($B34="","",COUNTIF('02_예약표'!$D$87:$J$110,$B34)) | H34: =IF($B34="","",$C34-D34) | I34: =IF($B34="","",$C34-E34) | J34: =IF($B34="","",$C34-F34) | K34: =IF($B34="","",$C34-G34)
A36: 주차별 전체 예약 블럭 | D36: =COUNTA('02_예약표'!$D$6:$J$29)-COUNTIF('02_예약표'!$D$6:$J$29,"수업 시간") | E36: =COUNTA('02_예약표'!$D$33:$J$56)-COUNTIF('02_예약표'!$D$33:$J$56,"수업 시간") | F36: =COUNTA('02_예약표'!$D$60:$J$83)-COUNTIF('02_예약표'!$D$60:$J$83,"수업 시간") | G36: =COUNTA('02_예약표'!$D$87:$J$110)-COUNTIF('02_예약표'!$D$87:$J$110,"수업 시간")
A37: 주간 공급량 128블럭

Sheet 04_안내
B2: 렌더팜 사용 안내
C3: 자세한 사용법은 노션 가이드를 참고하세요. 이 시트는 신청과 예약만 다룹니다.
B5: 1. 신청
B6: 제출 항목 | C6: 팀 프로젝트명 / 팀장 학번 / 팀장 이메일 / 프로젝트 분량(분)
B7: 분량 기준 | C7: 최종 상영 길이. 렌더해야 할 전체 컷의 길이를 적어주세요.
B8: 접수 | C8: 01_신청서 탭에 팀별로 한 줄씩 작성
B10: 2. 타임블럭과 그룹
B11: 타임블럭 1개 | C11: 4시간
B12: 평일 (월~금) | C12: 19:00 ~ 11:00 만 사용 가능 → 하루 4블럭 (낮 11~19시는 수업)
B13: 주말 (토·일) | C13: 24시간 → 하루 6블럭
B14: PC 그룹 | C14: A · B · C · D 네 묶음. 한 시간대에 네 팀이 동시에 렌더
B15: 주간 공급량 | C15: 평일 5×4×4 = 80 + 주말 2×6×4 = 48 → 총 128블럭
B17: 3. 라이선스 배정
B18: 라이선스 1개 | C18: 주 8블럭 = 32시간
B19: 3분 이하 | C19: 라이선스 1 · 주 8블럭
B20: 3분 초과 ~ 6분 이하 | C20: 라이선스 2 · 주 16블럭
B21: 6분 초과 | C21: 라이선스 3 · 주 24블럭
C22: 라이선스 합계가 16을 넘으면(128블럭 초과) 산정 기준을 조정해야 합니다.
C23: 라이선스는 상한선이며 할당량이 아닙니다. 블록은 선착순입니다.
B25: 4. 예약
B26: 방법 | C26: 02_예약표에서 시간 + 그룹을 고르고 빈 칸에 본인 학번 입력
B27: 제출할 때 | C27: Deadline 제출 창의 Pool / Group 을 예약한 그룹과 똑같이 지정
B28: 미등록 학번 | C28: 자동 삭제됩니다
B29: 안 쓰는 블록 | C29: 미리 비워주세요. 그래야 다른 팀이 씁니다
B30: 심야 블록 | C30: 23-03 / 03-07 이 가장 한가합니다. 저녁에 제출하고 자면 됩니다
B31: PC 로그인 | C31: 예약한 시간에만 Worker PC를 사용하세요
B33: 5. 위반 시
B34: 위반 유형 | C34: 타 학번으로 예약 / 타인 예약 수정·가로채기 / 예약 없이 제출 / 블록 선점 후 방치
B35: 1회 | C35: 경고 및 기록 공유
B36: 2회 | C36: 해당 주 라이선스 −2블럭
B37: 3회 | C37: 3일간 렌더팜 사용 정지
B38: 4회 이상 | C38: 팀 렌더팜 사용권 박탈 (졸준위·지도교수 협의)
B40: 6. 문의
B41: 예약 · 타임블럭 배정 | C41: 졸업준비위원회
B42: 렌더 실패 · 장비 문제 | C42: 이상빈 (C393169)
